<?xml version="1.0" encoding="utf-8"?>
<robot name="abot"
	xmlns:xacro="http://www.ros.org/wiki/xacro">

	<link name="robot_left_wheel">
		<visual>
			<origin xyz="0 0 0" rpy="0 0 0" />
			<geometry>
				<mesh filename="package://abot_description/meshes/abot_left_wheel.STL" />
			</geometry>
			<material name="Red" />
		</visual>

		<collision>
			<origin xyz="0 0 0" rpy="0 0 0" />
			<geometry>
				<mesh filename="package://abot_description/meshes/abot_left_wheel.STL" />
			</geometry>
		</collision>
	</link>

	<link name="left_wheel">
		<visual>
			<origin xyz="0 0 0" rpy="${PI/2} 0 0" />
			<geometry>
				<cylinder length="${wheel_width}" radius="${wheel_radius}"/>
			</geometry>
			<material name="Red" />
		</visual>

		<collision>
			<origin xyz="0 0 0" rpy="${PI/2} 0 0" />
			<geometry>
				<cylinder length="${wheel_width}" radius="${wheel_radius}"/>
			</geometry>
		</collision>
	</link>

	<joint name="left_wheel_to_robot_left_wheel" type="fixed">
		<origin xyz="0 0 0" rpy="0 0 0" />
		<parent link="left_wheel" />
		<child link="robot_left_wheel" />
	</joint>
	
	<joint name="left_wheel_to_base" type="continuous">
		<origin xyz="0 0.205 0.03" rpy="0 0 0" />
		<parent link="robot_base" />
		<child link="left_wheel" />
		<axis xyz="0 1 0" />
	</joint>
</robot>
